<robot name = "robot">
    <link name="Link-x0">
        <inertial>
            <origin xyz="0 0 0.8096606811726296" rpy="0 0 0"/>
            <mass value="1" />
            <inertia ixx="100" ixy="0" ixz="0" iyy="100" iyz="0" izz="100" />
        </inertial>
        <visual>
            <origin xyz="0 0 0.8096606811726296" rpy="0 0 0"/>
            <geometry>
                <box size="0.5188064762652517 0.9589082011404115 0.8096606811726296" />
            </geometry>
            <material name="Green">
            		<color rgba="34 139 34 1.0"/>
            </material>
        </visual>
        <collision>
            <origin xyz="0 0 0.8096606811726296" rpy="0 0 0"/>
            <geometry>
                <box size="0.5188064762652517 0.9589082011404115 0.8096606811726296" />
            </geometry>
        </collision>
    </link>
    <joint name="Link-x0_Link-z1" type="revolute">
       <parent link="Link-x0"/>
       <child  link="Link-z1"/>
       <origin rpy="0 0 0" xyz="0 0 1.2144910217589444" />
       <axis xyz="1 0 0"/>
       <limit effort="0.0" lower="-3.14159" upper="3.14159" velocity="0.0"/>
    </joint>
    <link name="Link-z1">
        <inertial>
            <origin xyz="0 0 0.07781249795055795" rpy="0 0 0"/>
            <mass value="1" />
            <inertia ixx="100" ixy="0" ixz="0" iyy="100" iyz="0" izz="100" />
        </inertial>
        <visual>
            <origin xyz="0 0 0.07781249795055795" rpy="0 0 0"/>
            <geometry>
                <box size="0.9075668623485278 0.07003450525794896 0.1556249959011159" />
            </geometry>
            <material name="Green">
            		<color rgba="34 139 34 1.0"/>
            </material>
        </visual>
        <collision>
            <origin xyz="0 0 0.07781249795055795" rpy="0 0 0"/>
            <geometry>
                <box size="0.9075668623485278 0.07003450525794896 0.1556249959011159" />
            </geometry>
        </collision>
    </link>
    <joint name="Link-x0_Link-x2" type="revolute">
       <parent link="Link-x0"/>
       <child  link="Link-x2"/>
       <origin rpy="0 0 0" xyz="0.25940323813262584 0 0.8096606811726296" />
       <axis xyz="0 0 1"/>
       <limit effort="0.0" lower="-3.14159" upper="3.14159" velocity="0.0"/>
    </joint>
    <link name="Link-x2">
        <inertial>
            <origin xyz="0.25501621447407635 0 0" rpy="0 0 0"/>
            <mass value="1" />
            <inertia ixx="100" ixy="0" ixz="0" iyy="100" iyz="0" izz="100" />
        </inertial>
        <visual>
            <origin xyz="0.25501621447407635 0 0" rpy="0 0 0"/>
            <geometry>
                <box size="0.5100324289481527 0.5917958303148464 0.7632447362363" />
            </geometry>
            <material name="Blue">
            		<color rgba="0 0 139 1.0"/>
            </material>
        </visual>
        <collision>
            <origin xyz="0.25501621447407635 0 0" rpy="0 0 0"/>
            <geometry>
                <box size="0.5100324289481527 0.5917958303148464 0.7632447362363" />
            </geometry>
        </collision>
    </link>
    <joint name="Link-x2_Link-y3" type="revolute">
       <parent link="Link-x2"/>
       <child  link="Link-y3"/>
       <origin rpy="0 0 0" xyz="0 0.2958979151574232 0" />
       <axis xyz="0 0 1"/>
       <limit effort="0.0" lower="-3.14159" upper="3.14159" velocity="0.0"/>
    </joint>
    <link name="Link-y3">
        <inertial>
            <origin xyz="0 0.3040938442527883 0" rpy="0 0 0"/>
            <mass value="1" />
            <inertia ixx="100" ixy="0" ixz="0" iyy="100" iyz="0" izz="100" />
        </inertial>
        <visual>
            <origin xyz="0 0.3040938442527883 0" rpy="0 0 0"/>
            <geometry>
                <box size="0.08373874056435482 0.6081876885055766 0.39312140521446376" />
            </geometry>
            <material name="Green">
            		<color rgba="34 139 34 1.0"/>
            </material>
        </visual>
        <collision>
            <origin xyz="0 0.3040938442527883 0" rpy="0 0 0"/>
            <geometry>
                <box size="0.08373874056435482 0.6081876885055766 0.39312140521446376" />
            </geometry>
        </collision>
    </link>
    <joint name="Link-x2_Link-z4" type="revolute">
       <parent link="Link-x2"/>
       <child  link="Link-z4"/>
       <origin rpy="0 0 0" xyz="0 0 0.38162236811815" />
       <axis xyz="1 0 0"/>
       <limit effort="0.0" lower="-3.14159" upper="3.14159" velocity="0.0"/>
    </joint>
    <link name="Link-z4">
        <inertial>
            <origin xyz="0 0 0.21109876069552938" rpy="0 0 0"/>
            <mass value="1" />
            <inertia ixx="100" ixy="0" ixz="0" iyy="100" iyz="0" izz="100" />
        </inertial>
        <visual>
            <origin xyz="0 0 0.21109876069552938" rpy="0 0 0"/>
            <geometry>
                <box size="0.7093930205900036 0.2135669500635809 0.42219752139105876" />
            </geometry>
            <material name="Blue">
            		<color rgba="0 0 139 1.0"/>
            </material>
        </visual>
        <collision>
            <origin xyz="0 0 0.21109876069552938" rpy="0 0 0"/>
            <geometry>
                <box size="0.7093930205900036 0.2135669500635809 0.42219752139105876" />
            </geometry>
        </collision>
    </link>
    <joint name="Link-z4_Link-z5" type="revolute">
       <parent link="Link-z4"/>
       <child  link="Link-z5"/>
       <origin rpy="0 0 0" xyz="0 0 0.42219752139105876" />
       <axis xyz="1 0 0"/>
       <limit effort="0.0" lower="-3.14159" upper="3.14159" velocity="0.0"/>
    </joint>
    <link name="Link-z5">
        <inertial>
            <origin xyz="0 0 0.07724017566356978" rpy="0 0 0"/>
            <mass value="1" />
            <inertia ixx="100" ixy="0" ixz="0" iyy="100" iyz="0" izz="100" />
        </inertial>
        <visual>
            <origin xyz="0 0 0.07724017566356978" rpy="0 0 0"/>
            <geometry>
                <box size="0.7769734266057364 0.827886902774269 0.15448035132713955" />
            </geometry>
            <material name="Blue">
            		<color rgba="0 0 139 1.0"/>
            </material>
        </visual>
        <collision>
            <origin xyz="0 0 0.07724017566356978" rpy="0 0 0"/>
            <geometry>
                <box size="0.7769734266057364 0.827886902774269 0.15448035132713955" />
            </geometry>
        </collision>
    </link>
</robot>