<robot name = "robot">
    <joint name="Link-x0_Link-x1" type="revolute">
       <parent link="Link-x0"/>
       <child  link="Link-x1"/>
       <origin rpy="0 0 0" xyz="0.4476483386299135 0 0.7816666288541737" />
       <axis xyz="0 0 1"/>
       <limit effort="0.0" lower="-3.14159" upper="3.14159" velocity="0.0"/>
    </joint>
    <joint name="Link-x0_Link-z2" type="revolute">
       <parent link="Link-x0"/>
       <child  link="Link-z2"/>
       <origin rpy="0 0 0" xyz="0 0 1.1259148316933891" />
       <axis xyz="1 0 0"/>
       <limit effort="0.0" lower="-3.14159" upper="3.14159" velocity="0.0"/>
    </joint>
    <joint name="Link-x0_Link-y3" type="revolute">
       <parent link="Link-x0"/>
       <child  link="Link-y3"/>
       <origin rpy="0 0 0" xyz="0 0.056458703901615226 0.7816666288541737" />
       <axis xyz="0 0 1"/>
       <limit effort="0.0" lower="-3.14159" upper="3.14159" velocity="0.0"/>
    </joint>
    <link name="Link-x0">
        <inertial>
            <origin xyz="0 0 0.7816666288541737" rpy="0 0 0"/>
            <mass value="1" />
            <inertia ixx="100" ixy="0" ixz="0" iyy="100" iyz="0" izz="100" />
        </inertial>
        <visual>
            <origin xyz="0 0 0.7816666288541737" rpy="0 0 0"/>
            <geometry>
                <box size="0.895296677259827 0.11291740780323045 0.6884964056784307" />
            </geometry>
            <material name="Green">
            		<color rgba="0 0 100 1.0"/>
            </material>
        </visual>
        <collision>
            <origin xyz="0 0 0.7816666288541737" rpy="0 0 0"/>
            <geometry>
                <box size="0.895296677259827 0.11291740780323045 0.6884964056784307" />
            </geometry>
        </collision>
    </link>
    <link name="Link-x1">
        <inertial>
            <origin xyz="0.07610714326242901 0 0" rpy="0 0 0"/>
            <mass value="1" />
            <inertia ixx="100" ixy="0" ixz="0" iyy="100" iyz="0" izz="100" />
        </inertial>
        <visual>
            <origin xyz="0.07610714326242901 0 0" rpy="0 0 0"/>
            <geometry>
                <box size="0.15221428652485802 0.7180800175521804 0.7816666288541737" />
            </geometry>
            <material name="Green">
            		<color rgba="0 0 100 1.0"/>
            </material>
        </visual>
        <collision>
            <origin xyz="0.07610714326242901 0 0" rpy="0 0 0"/>
            <geometry>
                <box size="0.15221428652485802 0.7180800175521804 0.7816666288541737" />
            </geometry>
        </collision>
    </link>
    <link name="Link-z2">
        <inertial>
            <origin xyz="0 0 0.09040998058139144" rpy="0 0 0"/>
            <mass value="1" />
            <inertia ixx="100" ixy="0" ixz="0" iyy="100" iyz="0" izz="100" />
        </inertial>
        <visual>
            <origin xyz="0 0 0.09040998058139144" rpy="0 0 0"/>
            <geometry>
                <box size="0.9255454722226097 0.6669998354525085 0.18081996116278287" />
            </geometry>
            <material name="Blue">
            		<color rgba="1 1 139 1.0"/>
            </material>
        </visual>
        <collision>
            <origin xyz="0 0 0.09040998058139144" rpy="0 0 0"/>
            <geometry>
                <box size="0.9255454722226097 0.6669998354525085 0.18081996116278287" />
            </geometry>
        </collision>
    </link>
    <link name="Link-y3">
        <inertial>
            <origin xyz="0 0.41542842491201515 0" rpy="0 0 0"/>
            <mass value="1" />
            <inertia ixx="100" ixy="0" ixz="0" iyy="100" iyz="0" izz="100" />
        </inertial>
        <visual>
            <origin xyz="0 0.41542842491201515 0" rpy="0 0 0"/>
            <geometry>
                <box size="0.24713137692466225 0.8308568498240303 0.5048854687450784" />
            </geometry>
            <material name="Blue">
            		<color rgba="1 1 139 1.0"/>
            </material>
        </visual>
        <collision>
            <origin xyz="0 0.41542842491201515 0" rpy="0 0 0"/>
            <geometry>
                <box size="0.24713137692466225 0.8308568498240303 0.5048854687450784" />
            </geometry>
        </collision>
    </link>
</robot>