<robot name = "robot">
    <link name="Head">
        <inertial>
            <origin xyz="0 0 0.9290785088531935" rpy="0 0 0"/>
            <mass value="1" />
            <inertia ixx="100" ixy="0" ixz="0" iyy="100" iyz="0" izz="100" />
        </inertial>
        <visual>
            <origin xyz="0 0 0.9290785088531935" rpy="0 0 0"/>
            <geometry>
                <box size="0.99330110665343 0.14020201586286585 0.24133334006402363" />
            </geometry>
            <material name="Cyan">
            		<color rgba="0 191 255 1.0"/>
            </material>
        </visual>
        <collision>
            <origin xyz="0 0 0.9290785088531935" rpy="0 0 0"/>
            <geometry>
                <box size="0.99330110665343 0.14020201586286585 0.24133334006402363" />
            </geometry>
        </collision>
    </link>
    <joint name="Head_Link-y1" type="revolute">
       <parent link="Head"/>
       <child  link="Link-y1"/>
       <origin rpy="0 0 0" xyz="0 0.07010100793143292 0.9290785088531935" />
       <axis xyz="0 0 1"/>
       <limit effort="0.0" lower="-3.14159" upper="3.14159" velocity="0.0"/>
    </joint>
    <link name="Link-y1">
        <inertial>
            <origin xyz="0 0.21729381090497502 0" rpy="0 0 0"/>
            <mass value="1" />
            <inertia ixx="100" ixy="0" ixz="0" iyy="100" iyz="0" izz="100" />
        </inertial>
        <visual>
            <origin xyz="0 0.21729381090497502 0" rpy="0 0 0"/>
            <geometry>
                <box size="0.8265274659270198 0.43458762180995003 0.008834826308734889" />
            </geometry>
            <material name="Cyan">
            		<color rgba="0 191 255 1.0"/>
            </material>
        </visual>
        <collision>
            <origin xyz="0 0.21729381090497502 0" rpy="0 0 0"/>
            <geometry>
                <box size="0.8265274659270198 0.43458762180995003 0.008834826308734889" />
            </geometry>
        </collision>
    </link>
    <joint name="Link-y1_Link-x2" type="revolute">
       <parent link="Link-y1"/>
       <child  link="Link-x2"/>
       <origin rpy="0 0 0" xyz="0.4132637329635099 0.21729381090497502 0" />
       <axis xyz="0 0 1"/>
       <limit effort="0.0" lower="-3.14159" upper="3.14159" velocity="0.0"/>
    </joint>
    <link name="Link-x2">
        <inertial>
            <origin xyz="0.2734742899809594 0 0" rpy="0 0 0"/>
            <mass value="1" />
            <inertia ixx="100" ixy="0" ixz="0" iyy="100" iyz="0" izz="100" />
        </inertial>
        <visual>
            <origin xyz="0.2734742899809594 0 0" rpy="0 0 0"/>
            <geometry>
                <box size="0.5469485799619188 0.4338040993642286 0.7558102700653434" />
            </geometry>
            <material name="Green">
            		<color rgba="0 128 0 1.0"/>
            </material>
        </visual>
        <collision>
            <origin xyz="0.2734742899809594 0 0" rpy="0 0 0"/>
            <geometry>
                <box size="0.5469485799619188 0.4338040993642286 0.7558102700653434" />
            </geometry>
        </collision>
    </link>
    <joint name="Link-x2_Link-x3" type="revolute">
       <parent link="Link-x2"/>
       <child  link="Link-x3"/>
       <origin rpy="0 0 0" xyz="0.5469485799619188 0 0" />
       <axis xyz="0 1 1"/>
       <limit effort="0.0" lower="-3.14159" upper="3.14159" velocity="0.0"/>
    </joint>
    <link name="Link-x3">
        <inertial>
            <origin xyz="0.1636439384182355 0 0" rpy="0 0 0"/>
            <mass value="1" />
            <inertia ixx="100" ixy="0" ixz="0" iyy="100" iyz="0" izz="100" />
        </inertial>
        <visual>
            <origin xyz="0.1636439384182355 0 0" rpy="0 0 0"/>
            <geometry>
                <box size="0.327287876836471 0.624382644366813 0.35303816795585485" />
            </geometry>
            <material name="Cyan">
            		<color rgba="0 191 255 1.0"/>
            </material>
        </visual>
        <collision>
            <origin xyz="0.1636439384182355 0 0" rpy="0 0 0"/>
            <geometry>
                <box size="0.327287876836471 0.624382644366813 0.35303816795585485" />
            </geometry>
        </collision>
    </link>
    <joint name="Link-x3_Link-z4" type="revolute">
       <parent link="Link-x3"/>
       <child  link="Link-z4"/>
       <origin rpy="0 0 0" xyz="0.1636439384182355 0 0.17651908397792743" />
       <axis xyz="0 1 0"/>
       <limit effort="0.0" lower="-3.14159" upper="3.14159" velocity="0.0"/>
    </joint>
    <link name="Link-z4">
        <inertial>
            <origin xyz="0 0 0.28028473018706385" rpy="0 0 0"/>
            <mass value="1" />
            <inertia ixx="100" ixy="0" ixz="0" iyy="100" iyz="0" izz="100" />
        </inertial>
        <visual>
            <origin xyz="0 0 0.28028473018706385" rpy="0 0 0"/>
            <geometry>
                <box size="0.7509867933404144 0.9067520904515937 0.5605694603741277" />
            </geometry>
            <material name="Cyan">
            		<color rgba="0 191 255 1.0"/>
            </material>
        </visual>
        <collision>
            <origin xyz="0 0 0.28028473018706385" rpy="0 0 0"/>
            <geometry>
                <box size="0.7509867933404144 0.9067520904515937 0.5605694603741277" />
            </geometry>
        </collision>
    </link>
    <joint name="Link-z4_Link-y5" type="revolute">
       <parent link="Link-z4"/>
       <child  link="Link-y5"/>
       <origin rpy="0 0 0" xyz="0 0.45337604522579683 0.28028473018706385" />
       <axis xyz="1 0 0"/>
       <limit effort="0.0" lower="-3.14159" upper="3.14159" velocity="0.0"/>
    </joint>
    <link name="Link-y5">
        <inertial>
            <origin xyz="0 0.37302776397662385 0" rpy="0 0 0"/>
            <mass value="1" />
            <inertia ixx="100" ixy="0" ixz="0" iyy="100" iyz="0" izz="100" />
        </inertial>
        <visual>
            <origin xyz="0 0.37302776397662385 0" rpy="0 0 0"/>
            <geometry>
                <box size="0.039424577975163966 0.7460555279532477 0.48927452364249313" />
            </geometry>
            <material name="Cyan">
            		<color rgba="0 191 255 1.0"/>
            </material>
        </visual>
        <collision>
            <origin xyz="0 0.37302776397662385 0" rpy="0 0 0"/>
            <geometry>
                <box size="0.039424577975163966 0.7460555279532477 0.48927452364249313" />
            </geometry>
        </collision>
    </link>
    <joint name="Link-y5_Link-x6" type="revolute">
       <parent link="Link-y5"/>
       <child  link="Link-x6"/>
       <origin rpy="0 0 0" xyz="0.019712288987581983 0.37302776397662385 0" />
       <axis xyz="0 0 1"/>
       <limit effort="0.0" lower="-3.14159" upper="3.14159" velocity="0.0"/>
    </joint>
    <link name="Link-x6">
        <inertial>
            <origin xyz="0.3921953742387139 0 0" rpy="0 0 0"/>
            <mass value="1" />
            <inertia ixx="100" ixy="0" ixz="0" iyy="100" iyz="0" izz="100" />
        </inertial>
        <visual>
            <origin xyz="0.3921953742387139 0 0" rpy="0 0 0"/>
            <geometry>
                <box size="0.7843907484774278 0.7854457864055909 0.13486742031424537" />
            </geometry>
            <material name="Cyan">
            		<color rgba="0 191 255 1.0"/>
            </material>
        </visual>
        <collision>
            <origin xyz="0.3921953742387139 0 0" rpy="0 0 0"/>
            <geometry>
                <box size="0.7843907484774278 0.7854457864055909 0.13486742031424537" />
            </geometry>
        </collision>
    </link>
    <joint name="Link-x6_Link-x7" type="revolute">
       <parent link="Link-x6"/>
       <child  link="Link-x7"/>
       <origin rpy="0 0 0" xyz="0.7843907484774278 0 0" />
       <axis xyz="0 1 1"/>
       <limit effort="0.0" lower="-3.14159" upper="3.14159" velocity="0.0"/>
    </joint>
    <link name="Link-x7">
        <inertial>
            <origin xyz="0.07086324931180527 0 0" rpy="0 0 0"/>
            <mass value="1" />
            <inertia ixx="100" ixy="0" ixz="0" iyy="100" iyz="0" izz="100" />
        </inertial>
        <visual>
            <origin xyz="0.07086324931180527 0 0" rpy="0 0 0"/>
            <geometry>
                <box size="0.14172649862361053 0.41452856475741695 0.33540578734306536" />
            </geometry>
            <material name="Cyan">
            		<color rgba="0 191 255 1.0"/>
            </material>
        </visual>
        <collision>
            <origin xyz="0.07086324931180527 0 0" rpy="0 0 0"/>
            <geometry>
                <box size="0.14172649862361053 0.41452856475741695 0.33540578734306536" />
            </geometry>
        </collision>
    </link>
    <joint name="Link-x7_Link-x8" type="revolute">
       <parent link="Link-x7"/>
       <child  link="Link-x8"/>
       <origin rpy="0 0 0" xyz="0.14172649862361053 0 0" />
       <axis xyz="0 1 1"/>
       <limit effort="0.0" lower="-3.14159" upper="3.14159" velocity="0.0"/>
    </joint>
    <link name="Link-x8">
        <inertial>
            <origin xyz="0.32819814260866115 0 0" rpy="0 0 0"/>
            <mass value="1" />
            <inertia ixx="100" ixy="0" ixz="0" iyy="100" iyz="0" izz="100" />
        </inertial>
        <visual>
            <origin xyz="0.32819814260866115 0 0" rpy="0 0 0"/>
            <geometry>
                <box size="0.6563962852173223 0.9300168687993656 0.7138032372521665" />
            </geometry>
            <material name="Cyan">
            		<color rgba="0 191 255 1.0"/>
            </material>
        </visual>
        <collision>
            <origin xyz="0.32819814260866115 0 0" rpy="0 0 0"/>
            <geometry>
                <box size="0.6563962852173223 0.9300168687993656 0.7138032372521665" />
            </geometry>
        </collision>
    </link>
    <joint name="Link-x8_Link-y9" type="revolute">
       <parent link="Link-x8"/>
       <child  link="Link-y9"/>
       <origin rpy="0 0 0" xyz="0.32819814260866115 0.4650084343996828 0" />
       <axis xyz="0 0 1"/>
       <limit effort="0.0" lower="-3.14159" upper="3.14159" velocity="0.0"/>
    </joint>
    <link name="Link-y9">
        <inertial>
            <origin xyz="0 0.28786840354388177 0" rpy="0 0 0"/>
            <mass value="1" />
            <inertia ixx="100" ixy="0" ixz="0" iyy="100" iyz="0" izz="100" />
        </inertial>
        <visual>
            <origin xyz="0 0.28786840354388177 0" rpy="0 0 0"/>
            <geometry>
                <box size="0.602690853396696 0.5757368070877635 0.49614004487955676" />
            </geometry>
            <material name="Green">
            		<color rgba="0 128 0 1.0"/>
            </material>
        </visual>
        <collision>
            <origin xyz="0 0.28786840354388177 0" rpy="0 0 0"/>
            <geometry>
                <box size="0.602690853396696 0.5757368070877635 0.49614004487955676" />
            </geometry>
        </collision>
    </link>
    <joint name="Link-y9_Link-x10" type="revolute">
       <parent link="Link-y9"/>
       <child  link="Link-x10"/>
       <origin rpy="0 0 0" xyz="0.301345426698348 0.28786840354388177 0" />
       <axis xyz="0 0 1"/>
       <limit effort="0.0" lower="-3.14159" upper="3.14159" velocity="0.0"/>
    </joint>
    <link name="Link-x10">
        <inertial>
            <origin xyz="0.1315030570888608 0 0" rpy="0 0 0"/>
            <mass value="1" />
            <inertia ixx="100" ixy="0" ixz="0" iyy="100" iyz="0" izz="100" />
        </inertial>
        <visual>
            <origin xyz="0.1315030570888608 0 0" rpy="0 0 0"/>
            <geometry>
                <box size="0.2630061141777216 0.628216471847177 0.9290785088531935" />
            </geometry>
            <material name="Cyan">
            		<color rgba="0 191 255 1.0"/>
            </material>
        </visual>
        <collision>
            <origin xyz="0.1315030570888608 0 0" rpy="0 0 0"/>
            <geometry>
                <box size="0.2630061141777216 0.628216471847177 0.9290785088531935" />
            </geometry>
        </collision>
    </link>
    <joint name="Link-x10_Link-x11" type="revolute">
       <parent link="Link-x10"/>
       <child  link="Link-x11"/>
       <origin rpy="0 0 0" xyz="0.2630061141777216 0 0" />
       <axis xyz="0 1 1"/>
       <limit effort="0.0" lower="-3.14159" upper="3.14159" velocity="0.0"/>
    </joint>
    <link name="Link-x11">
        <inertial>
            <origin xyz="0.49186859318901777 0 0" rpy="0 0 0"/>
            <mass value="1" />
            <inertia ixx="100" ixy="0" ixz="0" iyy="100" iyz="0" izz="100" />
        </inertial>
        <visual>
            <origin xyz="0.49186859318901777 0 0" rpy="0 0 0"/>
            <geometry>
                <box size="0.9837371863780355 0.049756810162816856 0.06413085067861901" />
            </geometry>
            <material name="Cyan">
            		<color rgba="0 191 255 1.0"/>
            </material>
        </visual>
        <collision>
            <origin xyz="0.49186859318901777 0 0" rpy="0 0 0"/>
            <geometry>
                <box size="0.9837371863780355 0.049756810162816856 0.06413085067861901" />
            </geometry>
        </collision>
    </link>
</robot>