<robot name = "robot">
    <link name="Link-x0">
        <inertial>
            <origin xyz="0 0 0.9999158060195243" rpy="0 0 0"/>
            <mass value="1" />
            <inertia ixx="100" ixy="0" ixz="0" iyy="100" iyz="0" izz="100" />
        </inertial>
        <visual>
            <origin xyz="0 0 0.9999158060195243" rpy="0 0 0"/>
            <geometry>
                <box size="0.8169373613746115 0.4246761914937198 0.714440780299139" />
            </geometry>
            <material name="Blue">
            		<color rgba="0 0 139 1.0"/>
            </material>
        </visual>
        <collision>
            <origin xyz="0 0 0.9999158060195243" rpy="0 0 0"/>
            <geometry>
                <box size="0.8169373613746115 0.4246761914937198 0.714440780299139" />
            </geometry>
        </collision>
    </link>
    <joint name="Link-x0_Link-z1" type="revolute">
       <parent link="Link-x0"/>
       <child  link="Link-z1"/>
       <origin rpy="0 0 0" xyz="0 0 1.357136196169094" />
       <axis xyz="0 0 1"/>
       <limit effort="0.0" lower="-3.14159" upper="3.14159" velocity="0.0"/>
    </joint>
    <link name="Link-z1">
        <inertial>
            <origin xyz="0 0 0.2146375121746762" rpy="0 0 0"/>
            <mass value="1" />
            <inertia ixx="100" ixy="0" ixz="0" iyy="100" iyz="0" izz="100" />
        </inertial>
        <visual>
            <origin xyz="0 0 0.2146375121746762" rpy="0 0 0"/>
            <geometry>
                <box size="0.18275930546249253 0.22124138796233428 0.4292750243493524" />
            </geometry>
            <material name="Blue">
            		<color rgba="0 0 139 1.0"/>
            </material>
        </visual>
        <collision>
            <origin xyz="0 0 0.2146375121746762" rpy="0 0 0"/>
            <geometry>
                <box size="0.18275930546249253 0.22124138796233428 0.4292750243493524" />
            </geometry>
        </collision>
    </link>
    <joint name="Link-z1_Link-x2" type="revolute">
       <parent link="Link-z1"/>
       <child  link="Link-x2"/>
       <origin rpy="0 0 0" xyz="0.4154857200072506 0 0" />
       <axis xyz="1 0 0"/>
       <limit effort="0.0" lower="-3.14159" upper="3.14159" velocity="0.0"/>
    </joint>
    <link name="Link-x2">
        <inertial>
            <origin xyz="0.0314583177449731 0 0" rpy="0 0 0"/>
            <mass value="1" />
            <inertia ixx="100" ixy="0" ixz="0" iyy="100" iyz="0" izz="100" />
        </inertial>
        <visual>
            <origin xyz="0.0314583177449731 0 0" rpy="0 0 0"/>
            <geometry>
                <box size="0.0629166354899462 0.8548062895720026 0.5954286605739336" />
            </geometry>
            <material name="Blue">
            		<color rgba="0 0 139 1.0"/>
            </material>
        </visual>
        <collision>
            <origin xyz="0.0314583177449731 0 0" rpy="0 0 0"/>
            <geometry>
                <box size="0.0629166354899462 0.8548062895720026 0.5954286605739336" />
            </geometry>
        </collision>
    </link>
    <joint name="Link-z1_Link-y3" type="revolute">
       <parent link="Link-z1"/>
       <child  link="Link-y3"/>
       <origin rpy="0 0 0" xyz="0 0.13775113243670017 0" />
       <axis xyz="0 1 0"/>
       <limit effort="0.0" lower="-3.14159" upper="3.14159" velocity="0.0"/>
    </joint>
    <link name="Link-y3">
        <inertial>
            <origin xyz="0 0.25497512849319054 0" rpy="0 0 0"/>
            <mass value="1" />
            <inertia ixx="100" ixy="0" ixz="0" iyy="100" iyz="0" izz="100" />
        </inertial>
        <visual>
            <origin xyz="0 0.25497512849319054 0" rpy="0 0 0"/>
            <geometry>
                <box size="0.151914638725962 0.5099502569863811 0.6237127179144237" />
            </geometry>
            <material name="Blue">
            		<color rgba="0 0 139 1.0"/>
            </material>
        </visual>
        <collision>
            <origin xyz="0 0.25497512849319054 0" rpy="0 0 0"/>
            <geometry>
                <box size="0.151914638725962 0.5099502569863811 0.6237127179144237" />
            </geometry>
        </collision>
    </link>
    <joint name="Link-z1_Link-z4" type="revolute">
       <parent link="Link-z1"/>
       <child  link="Link-z4"/>
       <origin rpy="0 0 0" xyz="0 0 0.4292750243493524" />
       <axis xyz="0 0 1"/>
       <limit effort="0.0" lower="-3.14159" upper="3.14159" velocity="0.0"/>
    </joint>
    <link name="Link-z4">
        <inertial>
            <origin xyz="0 0 0.20794447588395787" rpy="0 0 0"/>
            <mass value="1" />
            <inertia ixx="100" ixy="0" ixz="0" iyy="100" iyz="0" izz="100" />
        </inertial>
        <visual>
            <origin xyz="0 0 0.20794447588395787" rpy="0 0 0"/>
            <geometry>
                <box size="0.06454820168397479 0.1809120781781235 0.41588895176791574" />
            </geometry>
            <material name="Blue">
            		<color rgba="0 0 139 1.0"/>
            </material>
        </visual>
        <collision>
            <origin xyz="0 0 0.20794447588395787" rpy="0 0 0"/>
            <geometry>
                <box size="0.06454820168397479 0.1809120781781235 0.41588895176791574" />
            </geometry>
        </collision>
    </link>
    <joint name="Link-z4_Link-y5" type="revolute">
       <parent link="Link-z4"/>
       <child  link="Link-y5"/>
       <origin rpy="0 0 0" xyz="0 0.040686337673459194 0" />
       <axis xyz="0 1 0"/>
       <limit effort="0.0" lower="-3.14159" upper="3.14159" velocity="0.0"/>
    </joint>
    <link name="Link-y5">
        <inertial>
            <origin xyz="0 0.42181512072446553 0" rpy="0 0 0"/>
            <mass value="1" />
            <inertia ixx="100" ixy="0" ixz="0" iyy="100" iyz="0" izz="100" />
        </inertial>
        <visual>
            <origin xyz="0 0.42181512072446553 0" rpy="0 0 0"/>
            <geometry>
                <box size="0.01078952257438337 0.8436302414489311 0.7840452055685069" />
            </geometry>
            <material name="Green">
            		<color rgba="34 139 34 1.0"/>
            </material>
        </visual>
        <collision>
            <origin xyz="0 0.42181512072446553 0" rpy="0 0 0"/>
            <geometry>
                <box size="0.01078952257438337 0.8436302414489311 0.7840452055685069" />
            </geometry>
        </collision>
    </link>
    <joint name="Link-z4_Link-z6" type="revolute">
       <parent link="Link-z4"/>
       <child  link="Link-z6"/>
       <origin rpy="0 0 0" xyz="0 0 0.41588895176791574" />
       <axis xyz="0 0 1"/>
       <limit effort="0.0" lower="-3.14159" upper="3.14159" velocity="0.0"/>
    </joint>
    <link name="Link-z6">
        <inertial>
            <origin xyz="0 0 0.2628953551496759" rpy="0 0 0"/>
            <mass value="1" />
            <inertia ixx="100" ixy="0" ixz="0" iyy="100" iyz="0" izz="100" />
        </inertial>
        <visual>
            <origin xyz="0 0 0.2628953551496759" rpy="0 0 0"/>
            <geometry>
                <box size="0.20257320978890958 0.9472793471637014 0.5257907102993518" />
            </geometry>
            <material name="Blue">
            		<color rgba="0 0 139 1.0"/>
            </material>
        </visual>
        <collision>
            <origin xyz="0 0 0.2628953551496759" rpy="0 0 0"/>
            <geometry>
                <box size="0.20257320978890958 0.9472793471637014 0.5257907102993518" />
            </geometry>
        </collision>
    </link>
</robot>